Workbook

Sheet Form Responses 1
A1: Timestamp | B1: Apakah anda bersedia untuk berpartisipasi? | C1: Apakah status Anda saat ini adalah mahasiswa aktif di sebuah perguruan tinggi di Jawa Barat? | D1: Nama (Inisial) | E1: Jenis Kelamin | F1: Usia Anda saat ini (dalam angka): | G1: Asal Perguruan Tinggi | H1: Fakultas/Program Studi | I1: Semester yang anda jalani saat ini | J1: Daerah tempat tinggal saat ini | K1: Mana yang paling menggambarkan area tempat tinggal Anda saat ini? | L1: Selama berkuliah, jenis tempat tinggal utama Anda adalah: | M1: Saya senang menghabiskan waktu di luar ruangan, terutama di lingkungan alami (seperti hutan, pegunungan, sungai, lapangan, taman kota, danau atau pantai, maupun halaman atau kebun yang rindang). | N1: Saya menganggap diri saya sebagai bagian dari alam, bukan sesuatu yang terpisah darinya. | O1: Jika saya memiliki sumber daya seperti waktu atau uang yang cukup, saya akan menggunakan sebagian darinya untuk melindungi lingkungan alam. | P1: Ketika saya merasa kesal atau stres, menghabiskan waktu di alam terbuka mampu membuat saya merasa lebih baik. | Q1: Saya merasa memiliki banyak kesamaan dengan hewan-hewan yang hidup di alam liar. | R1: Berperilaku secara bertanggung jawab terhadap alam—misalnya menjalani gaya hidup berkelanjutan—merupakan bagian penting dari diri saya. | S1: Mempelajari alam seharusnya menjadi bagian dari pendidikan setiap orang sejak dini. | T1: Jika bisa memilih, saya lebih suka tinggal di tempat yang memiliki pemandangan alam, seperti pepohonan atau ruang hijau terbuka. | U1: Ada bagian penting dalam hidup saya yang terasa hilang jika saya tidak sesekali bisa keluar dan menikmati alam. | V1: Saya merasa ada bagian-bagian dari alam yang lebih indah dari karya seni apa pun. | W1: Ini adalah pertanyaan untuk memastikan Anda membaca dengan teliti. Mohon pilih jawaban "Biru". | X1: Saya merasa segar kembali setelah menghabiskan waktu di alam. | Y1: Saya memandang diri saya memiliki peran untuk menjaga kelestarian sumber daya alam. | Z1: Saya merasa nyaman berada di alam (seperti di hutan, di gunung, atau di pantai). | AA1: Saya menikmati unsur alam yang saya lihat seperti pepohonan atau rumput bahkan ketika saya berada di tengah kota. | AB1: Pengalaman saya berinteraksi dengan alam ikut membentuk cara saya memahami diri saya sendiri. | AC1: Hubungan saya dengan alam merupakan bagian dari cerita hidup saya. | AD1: Cara saya memandang hidup dipengaruhi oleh keyakinan bahwa manusia adalah bagian dari alam. | AE1: Ketika mengambil keputusan penting, saya mempertimbangkan hubungan saya dengan alam. | AF1: Bertindak ramah lingkungan adalah bagian penting dari diri saya. | AG1: Saya adalah tipe orang yang bertindak ramah lingkungan. | AH1: Saya melihat diri saya sebagai orang yang ramah lingkungan. | AI1: Saya tetap berusaha berperilaku ramah lingkungan meskipun membutuhkan usaha lebih. | AJ1: Isu lingkungan yang saya pahami memengaruhi cara saya memandang diri sebagai pribadi yang ramah lingkungan. | AK1: Saya tetap konsisten berperilaku ramah lingkungan sekalipun orang-orang di sekitar saya tidak melakukannya. | AL1: Saya tidak takut menyampaikan pendapat saya, meskipun berbeda dengan pendapat kebanyakan orang. | AM1: Keputusan yang saya buat biasanya tidak dipengaruhi oleh apa yang dilakukan oleh orang lain. | AN1: Saya cenderung khawatir dengan apa yang dipikirkan orang lain tentang diri saya. | AO1: Saya cenderung mudah dipengaruhi oleh orang yang pendapatnya lebih kuat. | AP1: Saya merasa percaya diri atas pendapat saya, meskipun berbeda dari pandangan kebanyakan orang. | AQ1: Sulit bagi saya untuk menyampaikan pendapat pribadi saya mengenai isu-isu yang kontroversial. | AR1: Saya menilai diri saya berdasarkan apa yang menurut saya penting, bukan berdasarkan apa yang orang lain anggap penting. | AS1: Secara umum, saya merasa memiliki kendali atas situasi dalam kehidupan saya. | AT1: Tuntutan hidup sehari-hari sering membuat hidup saya terasa lebih berat. | AU1: Saya merasa tidak cocok dengan orang-orang dan komunitas di sekitar saya. | AV1: Ini adalah pertanyaan untuk memastikan Anda membaca dengan teliti. Mohon pilih jawaban "Hijau Tua". | AW1: Saya cukup baik dalam mengelola berbagai tanggung jawab dalam kehidupan sehari-hari. | AX1: Saya sering merasa kewalahan dengan tanggung jawab yang saya miliki. | AY1: Saya sulit mengatur hidup saya dengan cara yang memuaskan saya. | AZ1: Saya berhasil menata tempat tinggal dan gaya hidup yang sangat sesuai dengan keinginan saya. | BA1: Saya tidak tertarik pada aktivitas yang dapat memperluas wawasan saya. | BB1: Penting bagi saya untuk memiliki pengalaman baru yang menantang cara saya dalam memandang diri sendiri dan dunia di sekitar saya. | BC1: Jika saya renungkan, saya merasa kurang berkembang sebagai pribadi dari tahun ke tahun. | BD1: Saya merasa telah banyak berkembang sebagai pribadi seiring berjalannya waktu. | BE1: Saya tidak menyukai situasi baru yang menuntut saya untuk mengubah kebiasaan lama saya. | BF1: Ini adalah pertanyaan untuk memastikan Anda membaca dengan teliti. Mohon pilih jawaban "Kuning". | BG1: Bagi saya, hidup merupakan proses belajar, perubahan, dan perkembangan yang terus berlangsung. | BH1: Saya sudah lama menyerah untuk melakukan perbaikan atau perubahan besar dalam hidup saya. | BI1: Kebanyakan orang menganggap saya sebagai pribadi yang penyayang dan penuh perhatian. | BJ1: Mempertahankan hubungan dekat dengan orang lain terasa sulit dan membuat saya merasa frustasi. | BK1: Saya merasa kesulitan memiliki teman dekat untuk berbagi kekhawatiran dan masalah pribadi saya. | BL1: Saya menikmati percakapan pribadi yang saling terbuka dengan anggota keluarga atau teman. | BM1: Orang lain akan menggambarkan saya sebagai pribadi yang murah hati dan bersedia meluangkan waktu untuk orang lain. | BN1: Saya tidak sering merasakan hubungan yang hangat dan saling percaya dengan orang lain. | BO1: Saya bisa mempercayai teman-teman saya, dan mereka pun mempercayai saya. | BP1: Saya menjalani hidup hari demi hari tanpa terlalu memikirkan masa depan. | BQ1: Saya memiliki arah dan tujuan hidup yang jelas. | BR1: Kegiatan sehari-hari saya sering terasa sepele dan tidak bermakna. | BS1: Saya tidak memiliki gambaran yang jelas tentang apa yang ingin saya capai dalam hidup. | BT1: Saya senang membuat rencana untuk masa depan dan berusaha mewujudkannya. | BU1: Ini adalah pertanyaan untuk memastikan Anda membaca dengan teliti. Mohon pilih jawaban "Ungu". | BV1: Berbeda dengan sebagian orang, saya menjalani hidup dengan arah dan tujuan yang jelas. | BW1: Saya merasa tidak banyak berkembang sebagai pribadi belakangan ini. | BX1: Ketika merefleksikan perjalanan hidup saya sampai hari ini, saya merasa puas dengan semua yang saya alami. | BY1: Secara umum, saya merasa yakin dan positif terhadap diri sendiri. | BZ1: Saya merasa orang-orang yang saya kenal hidupnya lebih berhasil dibandingkan saya. | CA1: Saya menyukai sebagian besar aspek dari kepribadian saya. | CB1: Dalam banyak hal, saya merasa kecewa dengan pencapaian hidup saya. | CC1: Saya kurang percaya diri dibandingkan kebanyakan orang lain. | CD1: Ketika membandingkan diri saya dengan teman-teman dekat, saya merasa senang dengan diri saya yang sesungguhnya. | CE1: Saya tahu cara membuat akun di media sosial. | CF1: Saya tahu cara menghapus akun saya di media sosial. | CG1: Saya tahu cara menonaktifkan akun saya di media sosial. | CH1: Saya tahu cara mengunggah konten, seperti foto, di akun media sosial saya. | CI1: Saya tahu cara menghapus konten yang tidak diinginkan di akun media sosial saya. | CJ1: Saya memahami hukum hak cipta yang berlaku di platform media sosial. | CK1: Saya tahu cara menangani konflik di media sosial dengan tepat. | CL1: Saya mengetahui tata krama atau kebijakan penggunaan media sosial di kampus atau organisasi saya. | CM1: Saya tahu bahwa platform media sosial mengontrol apa yang saya lihat di beranda media sosial saya. | CN1: Saya tahu bahwa informasi yang pernah saya unggah di media sosial dapat tersimpan secara permanen. | CO1: Ini adalah pertanyaan untuk memastikan Anda membaca dengan teliti. Mohon pilih jawaban "Hijau". | CP1: Saya tahu bahwa iklan yang saya lihat di media sosial sudah disesuaikan dengan apa yang sering saya cari atau sukai. | CQ1: Saya tahu cara memverifikasi apakah informasi yang dibagikan di media sosial itu benar. | CR1: Saya tahu cara menggunakan berbagai sumber informasi untuk memverifikasi informasi yang saya lihat di media sosial. | CS1: Saya dapat menilai apakah suatu informasi di media sosial dapat dipercaya atau tidak. | CT1: Saya memilah sampah kertas, plastik, dan logam untuk didaur ulang. | CU1: Saya menghemat penggunaan air atau energi (seperti mematikan lampu/kipas) di tempat tinggal saya. | CV1: Saya membeli produk yang ramah lingkungan atau hemat energi saat berbelanja. | CW1: Saya mengurangi penggunaan plastik sekali pakai (sedotan, kantong plastik, botol air sekali pakai) dalam kehidupan sehari-hari. | CX1: Saya menangani sampah elektronik (e-waste) dengan benar, misalnya membuang baterai atau ponsel bekas ke tempat pengumpulan khusus. | CY1: Saya membicarakan isu lingkungan kepada orang-orang di sekitar atau komunitas saya. | CZ1: Saya aktif berpartisipasi sebagai anggota dalam komunitas atau organisasi lingkungan. | DA1: Saya berkolaborasi dengan orang lain (teman, komunitas, atau kolega) untuk mengatasi masalah lingkungan di sekitar saya. | DB1: Saya membagikan konten atau informasi tentang isu lingkungan di media sosial (Instagram, TikTok, Twitter/X, YouTube, dll.). | DC1: Saya aktif mengikuti dan menyebarkan pesan dari kreator konten yang mempromosikan isu lingkungan. | DD1: Saya memberikan suara atau dukungan pada kebijakan/pemimpin yang berpihak pada kelestarian lingkungan lokal. | DE1: Saya menyampaikan aspirasi terkait isu lingkungan kepada pejabat atau instansi pemerintah, baik secara langsung maupun melalui email atau akun media sosial mereka. | DF1: Saya pernah menandatangani petisi (baik cetak maupun online) terkait isu perlindungan lingkungan. | DG1: Saya menyumbangkan uang atau dana untuk mendukung kegiatan perlindungan lingkungan di sekitar saya. | DH1: Ini adalah pertanyaan untuk memastikan Anda membaca dengan teliti. Mohon pilih jawaban "Orange". | DI1: Saya berpartisipasi dalam kampanye lingkungan (seperti tantangan tagar) di media sosial. | DJ1: Saya menjadi sukarelawan dalam kegiatan pemulihan (konservasi) lingkungan, seperti penanaman pohon, pembersihan sungai/pantai, atau perawatan ruang hijau. | DK1: Saya berpartisipasi menyumbangkan data atau memantau kondisi satwa liar di sekitar lingkungan saya. | DL1: Saya melaporkan informasi tentang ancaman terhadap keanekaragaman hayati, seperti perdagangan satwa liar ilegal, kepada lembaga konservasi atau pihak terkait. | DM1: Saya menata halaman rumah saya agar dapat menarik satwa liar yang tidak mengganggu (seperti burung liar atau serangga). | DN1: Email/e-wallet | DO1: Email Address
A2: 46249.42 | B2: Ya, saya bersedia berpartisipasi. | C2: Ya | D2: H | E2: Perempuan | F2: 19 | G2: IPB UNIVERSITY | H2: Manajemen Agribisnis | I2: 3 | J2: Bodebekpunjur (Bogor, Depok, Bekasi, Puncak, Cianjur) | K2: Kota (Urban) | L2: Kos/Kontrakan | M2: Tidak Menggambarkan diri saya | N2: Cukup Menggambarkan diri saya | O2: Cukup Menggambarkan diri saya | P2: Cukup Tidak Menggambarkan diri saya | Q2: Tidak Menggambarkan diri saya | R2: Cukup Menggambarkan diri saya | S2: Sangat menggambarkan diri saya | T2: Menggambarkan diri saya | U2: Netral | V2: Sangat menggambarkan diri saya | W2: Biru | X2: Cukup Menggambarkan diri saya | Y2: Menggambarkan diri saya | Z2: Netral | AA2: Menggambarkan diri saya | AB2: Netral | AC2: Netral | AD2: Menggambarkan diri saya | AE2: Netral | AF2: Setuju | AG2: Cukup Setuju | AH2: Netral | AI2: Cukup Setuju | AJ2: Cukup Setuju | AK2: Cukup Setuju | AL2: Cukup Setuju | AM2: Setuju | AN2: Cukup Setuju | AO2: Cukup Setuju | AP2: Cukup Setuju | AQ2: Setuju | AR2: Setuju | AS2: Setuju | AT2: Cukup Setuju | AU2: Cukup Setuju | AV2: Hijau Tua | AW2: Setuju | AX2: Cukup Setuju | AY2: Cukup Tidak Setuju | AZ2: Sangat Setuju | BA2: Tidak Setuju | BB2: Setuju | BC2: Cukup Setuju | BD2: Cukup Setuju | BE2: Cukup Setuju | BF2: Kuning | BG2: Setuju | BH2: Tidak Setuju | BI2: Cukup Setuju | BJ2: Tidak Setuju | BK2: Cukup Setuju | BL2: Setuju | BM2: Cukup Tidak Setuju | BN2: Tidak Setuju | BO2: Cukup Setuju | BP2: Cukup Tidak Setuju | BQ2: Cukup Setuju | BR2: Cukup Setuju | BS2: Tidak Setuju | BT2: Setuju | BU2: Ungu | BV2: Cukup Setuju | BW2: Cukup Tidak Setuju | BX2: Cukup Setuju | BY2: Setuju | BZ2: Cukup Tidak Setuju | CA2: Setuju | CB2: Tidak Setuju | CC2: Cukup Tidak Setuju | CD2: Cukup Setuju | CE2: Sangat Setuju | CF2: Sangat Setuju | CG2: Sangat Setuju | CH2: Sangat Setuju | CI2: Sangat Setuju | CJ2: Setuju | CK2: Sangat Setuju | CL2: Sangat Setuju | CM2: Sangat Setuju | CN2: Sangat Setuju | CO2: Hijau | CP2: Sangat Setuju | CQ2: Sangat Setuju | CR2: Sangat Setuju | CS2: Sangat Setuju | CT2: Kadang-Kadang | CU2: Sering | CV2: Kadang-Kadang | CW2: Sering | CX2: Jarang | CY2: Kadang-Kadang | CZ2: Jarang | DA2: Kadang-Kadang | DB2: Kadang-Kadang | DC2: Kadang-Kadang | DD2: Jarang | DE2: Jarang | DF2: Tidak Pernah | DG2: Tidak Pernah | DH2: Ungu | DI2: Kadang-Kadang | DJ2: Jarang | DK2: Tidak Pernah | DL2: Tidak Pernah | DM2: Kadang-Kadang | DN2: hanifahainun131@gmail.com
A3: 46249.421 | B3: Ya, saya bersedia berpartisipasi. | C3: Ya | D3: WAR | E3: Perempuan | F3: 21 | G3: IPB University | H3: Sekolah Vokasi | I3: 5 | J3: Bodebekpunjur (Bogor, Depok, Bekasi, Puncak, Cianjur) | K3: Pinggiran Kota (Sub Urban) | L3: Rumah Orang Tua/Wali | M3: Sangat menggambarkan diri saya | N3: Cukup Menggambarkan diri saya | O3: Menggambarkan diri saya | P3: Menggambarkan diri saya | Q3: Tidak Menggambarkan diri saya | R3: Menggambarkan diri saya | S3: Cukup Menggambarkan diri saya | T3: Sangat menggambarkan diri saya | U3: Cukup Tidak Menggambarkan diri saya | V3: Cukup Menggambarkan diri saya | W3: Biru | X3: Menggambarkan diri saya | Y3: Sangat menggambarkan diri saya | Z3: Menggambarkan diri saya | AA3: Sangat menggambarkan diri saya | AB3: Cukup Menggambarkan diri saya | AC3: Menggambarkan diri saya | AD3: Menggambarkan diri saya | AE3: Cukup Tidak Menggambarkan diri saya | AF3: Setuju | AG3: Cukup Setuju | AH3: Netral | AI3: Cukup Setuju | AJ3: Setuju | AK3: Setuju | AL3: Cukup Setuju | AM3: Setuju | AN3: Cukup Setuju | AO3: Cukup Tidak Setuju | AP3: Cukup Setuju | AQ3: Cukup Tidak Setuju | AR3: Sangat Setuju | AS3: Sangat Setuju | AT3: Setuju | AU3: Cukup Tidak Setuju | AV3: Hijau Tua | AW3: Setuju | AX3: Tidak Setuju | AY3: Cukup Setuju | AZ3: Cukup Setuju | BA3: Tidak Setuju | BB3: Setuju | BC3: Cukup Tidak Setuju | BD3: Cukup Setuju | BE3: Cukup Tidak Setuju | BF3: Kuning | BG3: Setuju | BH3: Tidak Setuju | BI3: Cukup Setuju | BJ3: Cukup Tidak Setuju | BK3: Cukup Setuju | BL3: Cukup Tidak Setuju | BM3: Cukup Setuju | BN3: Cukup Setuju | BO3: Cukup Setuju | BP3: Cukup Tidak Setuju | BQ3: Cukup Setuju | BR3: Cukup Setuju | BS3: Setuju | BT3: Cukup Setuju | BU3: Ungu | BV3: Setuju | BW3: Cukup Tidak Setuju | BX3: Cukup Tidak Setuju | BY3: Cukup Setuju | BZ3: Cukup Setuju | CA3: Cukup Setuju | CB3: Cukup Setuju | CC3: Cukup Setuju | CD3: Setuju | CE3: Sangat Setuju | CF3: Sangat Setuju | CG3: Sangat Setuju | CH3: Sangat Setuju | CI3: Sangat Setuju | CJ3: Sangat Setuju | CK3: Sangat Setuju | CL3: Sangat Setuju | CM3: Sangat Setuju | CN3: Sangat Setuju | CO3: Hijau | CP3: Sangat Setuju | CQ3: Sangat Setuju | CR3: Sangat Setuju | CS3: Sangat Setuju | CT3: Kadang-Kadang | CU3: Sering | CV3: Kadang-Kadang | CW3: Sering | CX3: Sering | CY3: Sering | CZ3: Sering | DA3: Kadang-Kadang | DB3: Kadang-Kadang | DC3: Sering | DD3: Selalu | DE3: Selalu | DF3: Sering | DG3: Kadang-Kadang | DH3: Ungu | DI3: Kadang-Kadang | DJ3: Sering | DK3: Sering | DL3: Sering | DM3: Kadang-Kadang | DN3: wandasretianan82@gmail.com
A4: 46249.423 | B4: Ya, saya bersedia berpartisipasi. | C4: Ya | D4: Rania | E4: Perempuan | F4: 19 | G4: IPB | H4: Manajemen Agribisnis | I4: 3 | J4: Bodebekpunjur (Bogor, Depok, Bekasi, Puncak, Cianjur) | K4: Kota (Urban) | L4: Rumah Orang Tua/Wali | M4: Netral | N4: Netral | O4: Netral | P4: Netral | Q4: Netral | R4: Netral | S4: Netral | T4: Netral | U4: Netral | V4: Netral | W4: Biru | X4: Cukup Menggambarkan diri saya | Y4: Netral | Z4: Netral | AA4: Netral | AB4: Netral | AC4: Netral | AD4: Netral | AE4: Netral | AF4: Setuju | AG4: Setuju | AH4: Setuju | AI4: Setuju | AJ4: Setuju | AK4: Setuju | AL4: Cukup Setuju | AM4: Cukup Setuju | AN4: Cukup Setuju | AO4: Cukup Setuju | AP4: Cukup Setuju | AQ4: Cukup Setuju | AR4: Cukup Setuju | AS4: Cukup Setuju | AT4: Cukup Setuju | AU4: Cukup Setuju | AV4: Hijau Tua | AW4: Cukup Setuju | AX4: Cukup Setuju | AY4: Cukup Tidak Setuju | AZ4: Cukup Setuju | BA4: Cukup Tidak Setuju | BB4: Cukup Setuju | BC4: Cukup Setuju | BD4: Cukup Setuju | BE4: Cukup Tidak Setuju | BF4: Kuning | BG4: Setuju | BH4: Cukup Tidak Setuju | BI4: Cukup Setuju | BJ4: Cukup Tidak Setuju | BK4: Cukup Tidak Setuju | BL4: Cukup Setuju | BM4: Cukup Setuju | BN4: Cukup Tidak Setuju | BO4: Cukup Setuju | BP4: Cukup Tidak Setuju | BQ4: Cukup Setuju | BR4: Cukup Tidak Setuju | BS4: Cukup Tidak Setuju | BT4: Cukup Setuju | BU4: Ungu | BV4: Cukup Setuju | BW4: Cukup Tidak Setuju | BX4: Cukup Setuju | BY4: Cukup Setuju | BZ4: Cukup Setuju | CA4: Cukup Setuju | CB4: Cukup Tidak Setuju | CC4: Cukup Setuju | CD4: Cukup Setuju | CE4: Sangat Setuju | CF4: Setuju | CG4: Setuju | CH4: Sangat Setuju | CI4: Sangat Setuju | CJ4: Sangat Setuju | CK4: Sangat Setuju | CL4: Sangat Setuju | CM4: Sangat Setuju | CN4: Sangat Setuju | CO4: Hijau | CP4: Setuju | CQ4: Sangat Setuju | CR4: Sangat Setuju | CS4: Sangat Setuju | CT4: Selalu | CU4: Selalu | CV4: Selalu | CW4: Sering | CX4: Selalu | CY4: Kadang-Kadang | CZ4: Tidak Pernah | DA4: Tidak Pernah | DB4: Jarang | DC4: Kadang-Kadang | DD4: Kadang-Kadang | DE4: Tidak Pernah | DF4: Tidak Pernah | DG4: Jarang | DH4: Hijau | DI4: Jarang | DJ4: Jarang | DK4: Tidak Pernah | DL4: Tidak Pernah | DM4: Kadang-Kadang | DN4: raniaaliyafahiraa@gmail.com/ shopeepay 081213882207
A5: 46249.425 | B5: Ya, saya bersedia berpartisipasi. | C5: Ya | D5: S | E5: Perempuan | F5: 19 | G5: Sekolah Vokasi IPB University | H5: Akuntansi | I5: 3 | J5: Bodebekpunjur (Bogor, Depok, Bekasi, Puncak, Cianjur) | K5: Kota (Urban) | L5: Kos/Kontrakan | M5: Netral | N5: Cukup Menggambarkan diri saya | O5: Menggambarkan diri saya | P5: Cukup Menggambarkan diri saya | Q5: Netral | R5: Cukup Menggambarkan diri saya | S5: Menggambarkan diri saya | T5: Menggambarkan diri saya | U5: Netral | V5: Menggambarkan diri saya | W5: Biru | X5: Cukup Menggambarkan diri saya | Y5: Cukup Menggambarkan diri saya | Z5: Cukup Menggambarkan diri saya | AA5: Cukup Menggambarkan diri saya | AB5: Cukup Menggambarkan diri saya | AC5: Cukup Menggambarkan diri saya | AD5: Cukup Menggambarkan diri saya | AE5: Netral | AF5: Setuju | AG5: Setuju | AH5: Setuju | AI5: Setuju | AJ5: Setuju | AK5: Setuju | AL5: Setuju | AM5: Cukup Setuju | AN5: Cukup Setuju | AO5: Cukup Tidak Setuju | AP5: Cukup Setuju | AQ5: Cukup Tidak Setuju | AR5: Cukup Setuju | AS5: Cukup Setuju | AT5: Cukup Setuju | AU5: Cukup Tidak Setuju | AV5: Hijau Tua | AW5: Cukup Setuju | AX5: Cukup Setuju | AY5: Cukup Tidak Setuju | AZ5: Cukup Setuju | BA5: Cukup Tidak Setuju | BB5: Cukup Setuju | BC5: Cukup Tidak Setuju | BD5: Cukup Setuju | BE5: Cukup Tidak Setuju | BF5: Kuning | BG5: Setuju | BH5: Cukup Tidak Setuju | BI5: Cukup Setuju | BJ5: Cukup Tidak Setuju | BK5: Cukup Tidak Setuju | BL5: Cukup Setuju | BM5: Cukup Setuju | BN5: Cukup Tidak Setuju | BO5: Cukup Setuju | BP5: Cukup Tidak Setuju | BQ5: Cukup Setuju | BR5: Cukup Tidak Setuju | BS5: Cukup Tidak Setuju | BT5: Cukup Setuju | BU5: Ungu | BV5: Cukup Setuju | BW5: Cukup Tidak Setuju | BX5: Cukup Setuju | BY5: Cukup Setuju | BZ5: Cukup Tidak Setuju | CA5: Cukup Setuju | CB5: Cukup Tidak Setuju | CC5: Cukup Tidak Setuju | CD5: Cukup Setuju | CE5: Setuju | CF5: Setuju | CG5: Setuju | CH5: Setuju | CI5: Setuju | CJ5: Setuju | CK5: Setuju | CL5: Setuju | CM5: Setuju | CN5: Setuju | CO5: Hijau | CP5: Setuju | CQ5: Setuju | CR5: Setuju | CS5: Setuju | CT5: Kadang-Kadang | CU5: Selalu | CV5: Kadang-Kadang | CW5: Kadang-Kadang | CX5: Kadang-Kadang | CY5: Kadang-Kadang | CZ5: Kadang-Kadang | DA5: Kadang-Kadang | DB5: Kadang-Kadang | DC5: Kadang-Kadang | DD5: Kadang-Kadang | DE5: Kadang-Kadang | DF5: Kadang-Kadang | DG5: Kadang-Kadang | DH5: Hijau | DI5: Kadang-Kadang | DJ5: Kadang-Kadang | DK5: Kadang-Kadang | DL5: Kadang-Kadang | DM5: Kadang-Kadang | DN5: susilawati732007@gmail.com/083102566504-gopay
A6: 46249.429 | B6: Ya, saya bersedia berpartisipasi. | C6: Ya | D6: I | E6: Laki-laki | F6: 18 | G6: IPB | H6: Akuntansi | I6: 3 | J6: Bodebekpunjur (Bogor, Depok, Bekasi, Puncak, Cianjur) | K6: Pinggiran Kota (Sub Urban) | L6: Rumah Orang Tua/Wali | M6: Menggambarkan diri saya | N6: Cukup Menggambarkan diri saya | O6: Netral | P6: Cukup Menggambarkan diri saya | Q6: Cukup Tidak Menggambarkan diri saya | R6: Netral | S6: Cukup Menggambarkan diri saya | T6: Menggambarkan diri saya | U6: Netral | V6: Menggambarkan diri saya | W6: Biru | X6: Netral | Y6: Netral | Z6: Netral | AA6: Netral | AB6: Netral | AC6: Netral | AD6: Netral | AE6: Netral | AF6: Netral | AG6: Netral | AH6: Netral | AI6: Netral | AJ6: Netral | AK6: Netral | AL6: Cukup Setuju | AM6: Cukup Setuju | AN6: Cukup Tidak Setuju | AO6: Cukup Setuju | AP6: Cukup Setuju | AQ6: Cukup Tidak Setuju | AR6: Cukup Setuju | AS6: Cukup Tidak Setuju | AT6: Cukup Setuju | AU6: Cukup Tidak Setuju | AV6: Putih | AW6: Cukup Setuju | AX6: Cukup Tidak Setuju | AY6: Cukup Tidak Setuju | AZ6: Cukup Setuju | BA6: Cukup Setuju | BB6: Cukup Setuju | BC6: Cukup Setuju | BD6: Cukup Tidak Setuju | BE6: Cukup Setuju | BF6: Kuning | BG6: Cukup Tidak Setuju | BH6: Cukup Setuju | BI6: Cukup Setuju | BJ6: Cukup Tidak Setuju | BK6: Cukup Setuju | BL6: Cukup Tidak Setuju | BM6: Cukup Setuju | BN6: Cukup Tidak Setuju | BO6: Cukup Setuju | BP6: Cukup Tidak Setuju | BQ6: Cukup Tidak Setuju | BR6: Cukup Setuju | BS6: Cukup Tidak Setuju | BT6: Cukup Setuju | BU6: Putih | BV6: Cukup Setuju | BW6: Cukup Setuju | BX6: Cukup Tidak Setuju | BY6: Cukup Setuju | BZ6: Cukup Tidak Setuju | CA6: Cukup Setuju | CB6: Cukup Setuju | CC6: Cukup Setuju | CD6: Cukup Tidak Setuju | CE6: Netral | CF6: Netral | CG6: Netral | CH6: Netral | CI6: Netral | CJ6: Netral | CK6: Netral | CL6: Netral | CM6: Netral | CN6: Netral | CO6: Biru | CP6: Netral | CQ6: Netral | CR6: Netral | CS6: Netral | CT6: Kadang-Kadang | CU6: Kadang-Kadang | CV6: Kadang-Kadang | CW6: Kadang-Kadang | CX6: Kadang-Kadang | CY6: Kadang-Kadang | CZ6: Kadang-Kadang | DA6: Kadang-Kadang | DB6: Kadang-Kadang | DC6: Kadang-Kadang | DD6: Kadang-Kadang | DE6: Kadang-Kadang | DF6: Kadang-Kadang | DG6: Kadang-Kadang | DH6: Hijau | DI6: Kadang-Kadang | DJ6: Kadang-Kadang | DK6: Kadang-Kadang | DL6: Kadang-Kadang | DM6: Kadang-Kadang | DN6: -
A7: 46249.432 | B7: Ya, saya bersedia berpartisipasi. | C7: Ya | D7: M.F | E7: Laki-laki | F7: 20 | G7: IPB University | H7: Sekolah Vokasi/Akuntansi | I7: 5 | J7: Bodebekpunjur (Bogor, Depok, Bekasi, Puncak, Cianjur) | K7: Kota (Urban) | L7: Kos/Kontrakan | M7: Cukup Menggambarkan diri saya | N7: Cukup Menggambarkan diri saya | O7: Menggambarkan diri saya | P7: Netral | Q7: Netral | R7: Menggambarkan diri saya | S7: Cukup Menggambarkan diri saya | T7: Sangat menggambarkan diri saya | U7: Cukup Menggambarkan diri saya | V7: Menggambarkan diri saya | W7: Biru | X7: Cukup Menggambarkan diri saya | Y7: Cukup Menggambarkan diri saya | Z7: Menggambarkan diri saya | AA7: Cukup Menggambarkan diri saya | AB7: Menggambarkan diri saya | AC7: Cukup Menggambarkan diri saya | AD7: Cukup Menggambarkan diri saya | AE7: Cukup Menggambarkan diri saya | AF7: Setuju | AG7: Cukup Setuju | AH7: Cukup Setuju | AI7: Sangat Setuju | AJ7: Cukup Setuju | AK7: Cukup Setuju | AL7: Setuju | AM7: Cukup Setuju | AN7: Tidak Setuju | AO7: Cukup Tidak Setuju | AP7: Cukup Setuju | AQ7: Tidak Setuju | AR7: Sangat Setuju | AS7: Setuju | AT7: Setuju | AU7: Tidak Setuju | AV7: Hijau Tua | AW7: Cukup Setuju | AX7: Cukup Tidak Setuju | AY7: Cukup Setuju | AZ7: Setuju | BA7: Tidak Setuju | BB7: Cukup Setuju | BC7: Cukup Tidak Setuju | BD7: Cukup Setuju | BE7: Cukup Tidak Setuju | BF7: Kuning | BG7: Setuju | BH7: Cukup Setuju | BI7: Setuju | BJ7: Cukup Tidak Setuju | BK7: Cukup Tidak Setuju | BL7: Cukup Setuju | BM7: Cukup Setuju | BN7: Cukup Tidak Setuju | BO7: Cukup Setuju | BP7: Tidak Setuju | BQ7: Setuju | BR7: Cukup Tidak Setuju | BS7: Cukup Tidak Setuju | BT7: Setuju | BU7: Ungu | BV7: Cukup Setuju | BW7: Cukup Tidak Setuju | BX7: Setuju | BY7: Setuju | BZ7: Cukup Tidak Setuju | CA7: Cukup Setuju | CB7: Tidak Setuju | CC7: Cukup Setuju | CD7: Cukup Setuju | CE7: Setuju | CF7: Setuju | CG7: Setuju | CH7: Sangat Setuju | CI7: Setuju | CJ7: Setuju | CK7: Setuju | CL7: Sangat Setuju | CM7: Setuju | CN7: Setuju | CO7: Hijau | CP7: Setuju | CQ7: Setuju | CR7: Sangat Setuju | CS7: Setuju | CT7: Kadang-Kadang | CU7: Sering | CV7: Kadang-Kadang | CW7: Sering | CX7: Jarang | CY7: Kadang-Kadang | CZ7: Kadang-Kadang | DA7: Kadang-Kadang | DB7: Jarang | DC7: Jarang | DD7: Kadang-Kadang | DE7: Jarang | DF7: Kadang-Kadang | DG7: Jarang | DH7: Ungu | DI7: Kadang-Kadang | DJ7: Jarang | DK7: Tidak Pernah | DL7: Tidak Pernah | DM7: Kadang-Kadang | DN7: muhamadmaulanamiftahfarid@gmail.com
A8: 46249.432 | B8: Ya, saya bersedia berpartisipasi. | C8: Ya | D8: MS | E8: Perempuan | F8: 19 | G8: Institut Pertanian Bogor | H8: Sekolah Vokasi/Manajemen Industri | I8: 3 | J8: Purwasuka (Purwakarta, Subang, Karawang) | K8: Pinggiran Kota (Sub Urban) | L8: Kos/Kontrakan | M8: Menggambarkan diri saya | N8: Menggambarkan diri saya | O8: Sangat menggambarkan diri saya | P8: Sangat menggambarkan diri saya | Q8: Menggambarkan diri saya | R8: Sangat menggambarkan diri saya | S8: Menggambarkan diri saya | T8: Sangat menggambarkan diri saya | U8: Cukup Menggambarkan diri saya | V8: Menggambarkan diri saya | W8: Biru | X8: Menggambarkan diri saya | Y8: Sangat menggambarkan diri saya | Z8: Menggambarkan diri saya | AA8: Cukup Menggambarkan diri saya | AB8: Menggambarkan diri saya | AC8: Menggambarkan diri saya | AD8: Cukup Menggambarkan diri saya | AE8: Netral | AF8: Sangat Setuju | AG8: Cukup Setuju | AH8: Setuju | AI8: Cukup Setuju | AJ8: Setuju | AK8: Cukup Setuju | AL8: Cukup Setuju | AM8: Cukup Setuju | AN8: Setuju | AO8: Setuju | AP8: Cukup Setuju | AQ8: Cukup Setuju | AR8: Cukup Setuju | AS8: Cukup Setuju | AT8: Cukup Setuju | AU8: Tidak Setuju | AV8: Hijau Tua | AW8: Setuju | AX8: Cukup Setuju | AY8: Cukup Tidak Setuju | AZ8: Cukup Setuju | BA8: Sangat Tidak Setuju | BB8: Setuju | BC8: Setuju | BD8: Cukup Setuju | BE8: Cukup Setuju | BF8: Kuning | BG8: Setuju | BH8: Sangat Tidak Setuju | BI8: Setuju | BJ8: Sangat Tidak Setuju | BK8: Tidak Setuju | BL8: Cukup Setuju | BM8: Cukup Setuju | BN8: Tidak Setuju | BO8: Cukup Setuju | BP8: Sangat Tidak Setuju | BQ8: Cukup Tidak Setuju | BR8: Cukup Setuju | BS8: Cukup Setuju | BT8: Cukup Setuju | BU8: Ungu | BV8: Cukup Tidak Setuju | BW8: Cukup Setuju | BX8: Cukup Tidak Setuju | BY8: Setuju | BZ8: Cukup Setuju | CA8: Cukup Setuju | CB8: Cukup Tidak Setuju | CC8: Cukup Tidak Setuju | CD8: Tidak Setuju | CE8: Setuju | CF8: Setuju | CG8: Setuju | CH8: Setuju | CI8: Setuju | CJ8: Netral | CK8: Netral | CL8: Netral | CM8: Netral | CN8: Netral | CO8: Hijau | CP8: Setuju | CQ8: Netral | CR8: Netral | CS8: Netral | CT8: Kadang-Kadang | CU8: Sering | CV8: Kadang-Kadang | CW8: Sering | CX8: Kadang-Kadang | CY8: Sering | CZ8: Jarang | DA8: Tidak Pernah | DB8: Sering | DC8: Sering | DD8: Sering | DE8: Jarang | DF8: Tidak Pernah | DG8: Jarang | DH8: Ungu | DI8: Kadang-Kadang | DJ8: Tidak Pernah | DK8: Tidak Pernah | DL8: Kadang-Kadang | DM8: Sering | DN8: mustikaselviyani@apps.ipb.ac.id
A9: 46249.448 | B9: Ya, saya bersedia berpartisipasi. | C9: Ya | D9: Ainun | E9: Perempuan | F9: 19 | G9: IPB University | H9: Sekolah Vokasi/Manajemen Industri | I9: 3 | J9: Bodebekpunjur (Bogor, Depok, Bekasi, Puncak, Cianjur) | K9: Pinggiran Kota (Sub Urban) | L9: Rumah Orang Tua/Wali | M9: Cukup Menggambarkan diri saya | N9: Cukup Tidak Menggambarkan diri saya | O9: Menggambarkan diri saya | P9: Cukup Menggambarkan diri saya | Q9: Cukup Tidak Menggambarkan diri saya | R9: Sangat menggambarkan diri saya | S9: Cukup Menggambarkan diri saya | T9: Menggambarkan diri saya | U9: Menggambarkan diri saya | V9: Netral | W9: Biru | X9: Cukup Menggambarkan diri saya | Y9: Menggambarkan diri saya | Z9: Menggambarkan diri saya | AA9: Menggambarkan diri saya | AB9: Netral | AC9: Menggambarkan diri saya | AD9: Menggambarkan diri saya | AE9: Netral | AF9: Setuju | AG9: Cukup Setuju | AH9: Setuju | AI9: Cukup Setuju | AJ9: Setuju | AK9: Setuju | AL9: Cukup Setuju | AM9: Cukup Tidak Setuju | AN9: Cukup Setuju | AO9: Setuju | AP9: Cukup Setuju | AQ9: Cukup Setuju | AR9: Setuju | AS9: Cukup Setuju | AT9: Cukup Setuju | AU9: Cukup Setuju | AV9: Hijau Tua | AW9: Sangat Setuju | AX9: Tidak Setuju | AY9: Sangat Setuju | AZ9: Cukup Setuju | BA9: Sangat Tidak Setuju | BB9: Setuju | BC9: Tidak Setuju | BD9: Setuju | BE9: Setuju | BF9: Kuning | BG9: Sangat Setuju | BH9: Sangat Tidak Setuju | BI9: Setuju | BJ9: Sangat Tidak Setuju | BK9: Sangat Tidak Setuju | BL9: Sangat Setuju | BM9: Cukup Setuju | BN9: Tidak Setuju | BO9: Setuju | BP9: Sangat Tidak Setuju | BQ9: Sangat Setuju | BR9: Sangat Tidak Setuju | BS9: Tidak Setuju | BT9: Sangat Setuju | BU9: Ungu | BV9: Setuju | BW9: Setuju | BX9: Cukup Setuju | BY9: Setuju | BZ9: Cukup Setuju | CA9: Setuju | CB9: Tidak Setuju | CC9: Tidak Setuju | CD9: Tidak Setuju | CE9: Tidak Setuju | CF9: Setuju | CG9: Netral | CH9: Netral | CI9: Setuju | CJ9: Setuju | CK9: Sangat Setuju | CL9: Setuju | CM9: Netral | CN9: Setuju | CO9: Hijau | CP9: Tidak Setuju | CQ9: Setuju | CR9: Setuju | CS9: Setuju | CT9: Sering | CU9: Sering | CV9: Sering | CW9: Kadang-Kadang | CX9: Sering | CY9: Kadang-Kadang | CZ9: Sering | DA9: Kadang-Kadang | DB9: Kadang-Kadang | DC9: Sering | DD9: Kadang-Kadang | DE9: Kadang-Kadang | DF9: Sering | DG9: Sering | DH9: Ungu | DI9: Kadang-Kadang | DJ9: Sering | DK9: Sering | DL9: Kadang-Kadang | DM9: Kadang-Kadang | DN9: ainunnabila2806@gmail.com
A10: 46249.456 | B10: Ya, saya bersedia berpartisipasi. | C10: Ya | D10: S | E10: Perempuan | F10: 20 | G10: Institute Pertanian Bogor | H10: Manajemen Agribisnis | I10: 5 | J10: Bodebekpunjur (Bogor, Depok, Bekasi, Puncak, Cianjur) | K10: Pinggiran Kota (Sub Urban) | L10: Rumah Orang Tua/Wali | M10: Netral | N10: Cukup Menggambarkan diri saya | O10: Cukup Menggambarkan diri saya | P10: Menggambarkan diri saya | Q10: Menggambarkan diri saya | R10: Menggambarkan diri saya | S10: Cukup Menggambarkan diri saya | T10: Cukup Menggambarkan diri saya | U10: Cukup Menggambarkan diri saya | V10: Cukup Menggambarkan diri saya | W10: Biru | X10: Cukup Menggambarkan diri saya | Y10: Cukup Menggambarkan diri saya | Z10: Menggambarkan diri saya | AA10: Sangat menggambarkan diri saya | AB10: Menggambarkan diri saya | AC10: Menggambarkan diri saya | AD10: Menggambarkan diri saya | AE10: Menggambarkan diri saya | AF10: Sangat Setuju | AG10: Setuju | AH10: Setuju | AI10: Sangat Setuju | AJ10: Sangat Setuju | AK10: Setuju | AL10: Setuju | AM10: Cukup Setuju | AN10: Cukup Setuju | AO10: Cukup Setuju | AP10: Cukup Setuju | AQ10: Cukup Setuju | AR10: Cukup Setuju | AS10: Setuju | AT10: Setuju | AU10: Cukup Setuju | AV10: Hijau Tua | AW10: Cukup Setuju | AX10: Cukup Tidak Setuju | AY10: Cukup Setuju | AZ10: Cukup Tidak Setuju | BA10: Tidak Setuju | BB10: Cukup Setuju | BC10: Setuju | BD10: Cukup Tidak Setuju | BE10: Setuju | BF10: Kuning | BG10: Setuju | BH10: Cukup Tidak Setuju | BI10: Cukup Setuju | BJ10: Cukup Setuju | BK10: Setuju | BL10: Cukup Setuju | BM10: Cukup Setuju | BN10: Cukup Tidak Setuju | BO10: Cukup Setuju | BP10: Tidak Setuju | BQ10: Cukup Setuju | BR10: Cukup Tidak Setuju | BS10: Cukup Tidak Setuju | BT10: Setuju | BU10: Ungu | BV10: Cukup Setuju | BW10: Setuju | BX10: Cukup Tidak Setuju | BY10: Setuju | BZ10: Setuju | CA10: Setuju | CB10: Cukup Setuju | CC10: Cukup Setuju | CD10: Cukup Setuju | CE10: Sangat Setuju | CF10: Sangat Setuju | CG10: Sangat Setuju | CH10: Sangat Setuju | CI10: Sangat Setuju | CJ10: Sangat Setuju | CK10: Setuju | CL10: Sangat Setuju | CM10: Sangat Setuju | CN10: Sangat Setuju | CO10: Hijau | CP10: Setuju | CQ10: Setuju | CR10: Sangat Setuju | CS10: Setuju | CT10: Kadang-Kadang | CU10: Sering | CV10: Jarang | CW10: Jarang | CX10: Kadang-Kadang | CY10: Kadang-Kadang | CZ10: Jarang | DA10: Jarang | DB10: Kadang-Kadang | DC10: Sering | DD10: Selalu | DE10: Jarang | DF10: Jarang | DG10: Kadang-Kadang | DH10: Ungu | DI10: Kadang-Kadang | DJ10: Kadang-Kadang | DK10: Tidak Pernah | DL10: Kadang-Kadang | DM10: Jarang | DN10: sucioktapy10@gmail.com
A11: 46249.458 | B11: Ya, saya bersedia berpartisipasi. | C11: Ya | D11: Sam | E11: Laki-laki | F11: 19 | G11: IPB University | H11: Sekolah Vokasi | I11: 3 | J11: Bodebekpunjur (Bogor, Depok, Bekasi, Puncak, Cianjur) | K11: Pinggiran Kota (Sub Urban) | L11: Rumah Orang Tua/Wali | M11: Cukup Menggambarkan diri saya | N11: Menggambarkan diri saya | O11: Sangat menggambarkan diri saya | P11: Sangat menggambarkan diri saya | Q11: Netral | R11: Sangat menggambarkan diri saya | S11: Sangat menggambarkan diri saya | T11: Netral | U11: Sangat menggambarkan diri saya | V11: Sangat menggambarkan diri saya | W11: Biru | X11: Menggambarkan diri saya | Y11: Sangat menggambarkan diri saya | Z11: Menggambarkan diri saya | AA11: Sangat menggambarkan diri saya | AB11: Sangat menggambarkan diri saya | AC11: Sangat menggambarkan diri saya | AD11: Cukup Menggambarkan diri saya | AE11: Menggambarkan diri saya | AF11: Sangat Setuju | AG11: Setuju | AH11: Setuju | AI11: Setuju | AJ11: Sangat Setuju | AK11: Setuju | AL11: Setuju | AM11: Cukup Setuju | AN11: Setuju | AO11: Cukup Setuju | AP11: Setuju | AQ11: Cukup Setuju | AR11: Setuju | AS11: Sangat Setuju | AT11: Setuju | AU11: Tidak Setuju | AV11: Hijau Tua | AW11: Setuju | AX11: Cukup Tidak Setuju | AY11: Cukup Tidak Setuju | AZ11: Setuju | BA11: Sangat Tidak Setuju | BB11: Sangat Setuju | BC11: Tidak Setuju | BD11: Sangat Setuju | BE11: Cukup Setuju | BF11: Kuning | BG11: Sangat Setuju | BH11: Sangat Tidak Setuju | BI11: Cukup Setuju | BJ11: Sangat Tidak Setuju | BK11: Tidak Setuju | BL11: Sangat Setuju | BM11: Sangat Setuju | BN11: Tidak Setuju | BO11: Sangat Setuju | BP11: Sangat Tidak Setuju | BQ11: Sangat Setuju | BR11: Sangat Tidak Setuju | BS11: Tidak Setuju | BT11: Setuju | BU11: Ungu | BV11: Setuju | BW11: Cukup Tidak Setuju | BX11: Setuju | BY11: Sangat Setuju | BZ11: Cukup Tidak Setuju | CA11: Setuju | CB11: Cukup Tidak Setuju | CC11: Cukup Setuju | CD11: Setuju | CE11: Sangat Setuju | CF11: Sangat Setuju | CG11: Sangat Setuju | CH11: Sangat Setuju | CI11: Sangat Setuju | CJ11: Setuju | CK11: Sangat Setuju | CL11: Setuju | CM11: Sangat Setuju | CN11: Setuju | CO11: Hijau | CP11: Setuju | CQ11: Setuju | CR11: Setuju | CS11: Sangat Setuju | CT11: Kadang-Kadang | CU11: Selalu | CV11: Sering | CW11: Sering | CX11: Kadang-Kadang | CY11: Jarang | CZ11: Jarang | DA11: Kadang-Kadang | DB11: Sering | DC11: Kadang-Kadang | DD11: Sering | DE11: Tidak Pernah | DF11: Tidak Pernah | DG11: Jarang | DH11: Orange | DI11: Tidak Pernah | DJ11: Jarang | DK11: Kadang-Kadang | DL11: Jarang | DM11: Sering | DN11: 081380063411 (Shopeepay, samtama)
A12: 46249.469 | B12: Ya, saya bersedia berpartisipasi. | C12: Ya | D12: Salma I.M | E12: Perempuan | F12: 20 | G12: IPB University | H12: Sekolah Vokasi/Akuntansi | I12: 5 | J12: Purwasuka (Purwakarta, Subang, Karawang) | K12: Pedesaaan (Rural) | L12: Kos/Kontrakan | M12: Menggambarkan diri saya | N12: Menggambarkan diri saya | O12: Menggambarkan diri saya | P12: Sangat menggambarkan diri saya | Q12: Menggambarkan diri saya | R12: Sangat menggambarkan diri saya | S12: Sangat menggambarkan diri saya | T12: Sangat menggambarkan diri saya | U12: Sangat menggambarkan diri saya | V12: Sangat menggambarkan diri saya | W12: Biru | X12: Sangat menggambarkan diri saya | Y12: Menggambarkan diri saya | Z12: Sangat menggambarkan diri saya | AA12: Sangat menggambarkan diri saya | AB12: Menggambarkan diri saya | AC12: Menggambarkan diri saya | AD12: Menggambarkan diri saya | AE12: Menggambarkan diri saya | AF12: Sangat Setuju | AG12: Sangat Setuju | AH12: Sangat Setuju | AI12: Sangat Setuju | AJ12: Sangat Setuju | AK12: Sangat Setuju | AL12: Setuju | AM12: Setuju | AN12: Cukup Tidak Setuju | AO12: Tidak Setuju | AP12: Setuju | AQ12: Cukup Tidak Setuju | AR12: Sangat Setuju | AS12: Sangat Setuju | AT12: Sangat Setuju | AU12: Tidak Setuju | AV12: Hijau Tua | AW12: Setuju | AX12: Setuju | AY12: Tidak Setuju | AZ12: Cukup Setuju | BA12: Sangat Setuju | BB12: Cukup Setuju | BC12: Cukup Tidak Setuju | BD12: Tidak Setuju | BE12: Sangat Tidak Setuju | BF12: Kuning | BG12: Sangat Setuju | BH12: Sangat Tidak Setuju | BI12: Sangat Setuju | BJ12: Tidak Setuju | BK12: Sangat Tidak Setuju | BL12: Sangat Setuju | BM12: Sangat Setuju | BN12: Sangat Tidak Setuju | BO12: Sangat Setuju | BP12: Tidak Setuju | BQ12: Setuju | BR12: Sangat Tidak Setuju | BS12: Tidak Setuju | BT12: Setuju | BU12: Ungu | BV12: Cukup Setuju | BW12: Cukup Tidak Setuju | BX12: Tidak Setuju | BY12: Cukup Setuju | BZ12: Setuju | CA12: Setuju | CB12: Setuju | CC12: Tidak Setuju | CD12: Setuju | CE12: Sangat Setuju | CF12: Sangat Setuju | CG12: Sangat Setuju | CH12: Sangat Setuju | CI12: Sangat Setuju | CJ12: Sangat Setuju | CK12: Tidak Setuju | CL12: Sangat Setuju | CM12: Sangat Setuju | CN12: Sangat Setuju | CO12: Hijau | CP12: Sangat Setuju | CQ12: Setuju | CR12: Setuju | CS12: Setuju | CT12: Selalu | CU12: Selalu | CV12: Selalu | CW12: Kadang-Kadang | CX12: Tidak Pernah | CY12: Sering | CZ12: Tidak Pernah | DA12: Kadang-Kadang | DB12: Tidak Pernah | DC12: Sering | DD12: Sering | DE12: Tidak Pernah | DF12: Tidak Pernah | DG12: Kadang-Kadang | DH12: Orange | DI12: Kadang-Kadang | DJ12: Kadang-Kadang | DK12: Tidak Pernah | DL12: Tidak Pernah | DM12: Sering | DN12: 082127283500
A13: 46249.47 | B13: Ya, saya bersedia berpartisipasi. | C13: Ya | D13: Faw | E13: Perempuan | F13: 19 | G13: IPB University | H13: Sekolah vokasi/ Manajemen Agribisnis | I13: 3 | J13: Sukabumi dan Sekitarnya | K13: Pinggiran Kota (Sub Urban) | L13: Kos/Kontrakan | M13: Sangat menggambarkan diri saya | N13: Sangat menggambarkan diri saya | O13: Sangat menggambarkan diri saya | P13: Sangat menggambarkan diri saya | Q13: Cukup Menggambarkan diri saya | R13: Sangat menggambarkan diri saya | S13: Sangat menggambarkan diri saya | T13: Sangat menggambarkan diri saya | U13: Sangat menggambarkan diri saya | V13: Sangat menggambarkan diri saya | W13: Biru | X13: Sangat menggambarkan diri saya | Y13: Sangat menggambarkan diri saya | Z13: Sangat menggambarkan diri saya | AA13: Sangat menggambarkan diri saya | AB13: Sangat menggambarkan diri saya | AC13: Cukup Menggambarkan diri saya | AD13: Sangat menggambarkan diri saya | AE13: Sangat menggambarkan diri saya | AF13: Sangat Setuju | AG13: Sangat Setuju | AH13: Cukup Setuju | AI13: Sangat Setuju | AJ13: Sangat Setuju | AK13: Sangat Setuju | AL13: Sangat Setuju | AM13: Cukup Setuju | AN13: Cukup Setuju | AO13: Cukup Tidak Setuju | AP13: Sangat Setuju | AQ13: Cukup Tidak Setuju | AR13: Setuju | AS13: Sangat Setuju | AT13: Cukup Setuju | AU13: Tidak Setuju | AV13: Hijau Tua | AW13: Sangat Setuju | AX13: Cukup Tidak Setuju | AY13: Cukup Tidak Setuju | AZ13: Sangat Setuju | BA13: Sangat Tidak Setuju | BB13: Sangat Setuju | BC13: Sangat Tidak Setuju | BD13: Sangat Setuju | BE13: Sangat Tidak Setuju | BF13: Kuning | BG13: Sangat Setuju | BH13: Sangat Tidak Setuju | BI13: Cukup Setuju | BJ13: Tidak Setuju | BK13: Tidak Setuju | BL13: Sangat Setuju | BM13: Cukup Setuju | BN13: Sangat Tidak Setuju | BO13: Sangat Setuju | BP13: Tidak Setuju | BQ13: Setuju | BR13: Tidak Setuju | BS13: Tidak Setuju | BT13: Sangat Setuju | BU13: Ungu | BV13: Sangat Setuju | BW13: Tidak Setuju | BX13: Sangat Setuju | BY13: Setuju | BZ13: Cukup Tidak Setuju | CA13: Sangat Setuju | CB13: Cukup Tidak Setuju | CC13: Tidak Setuju | CD13: Setuju | CE13: Sangat Setuju | CF13: Sangat Setuju | CG13: Sangat Setuju | CH13: Sangat Setuju | CI13: Sangat Setuju | CJ13: Sangat Setuju | CK13: Setuju | CL13: Sangat Setuju | CM13: Sangat Setuju | CN13: Sangat Setuju | CO13: Hijau | CP13: Sangat Setuju | CQ13: Setuju | CR13: Sangat Setuju | CS13: Sangat Setuju | CT13: Kadang-Kadang | CU13: Selalu | CV13: Kadang-Kadang | CW13: Sering | CX13: Sering | CY13: Kadang-Kadang | CZ13: Jarang | DA13: Jarang | DB13: Sering | DC13: Sering | DD13: Selalu | DE13: Jarang | DF13: Kadang-Kadang | DG13: Sering | DH13: Orange | DI13: Selalu | DJ13: Kadang-Kadang | DK13: Kadang-Kadang | DL13: Jarang | DM13: Jarang | DN13: zahrariyana3@gmail.com
... A16: 46249.484 | B16: Ya, saya bersedia berpartisipasi. | C16: Ya | D16: Hilda | E16: Perempuan | F16: 19 | G16: Institut Pertanian Bogor | H16: Manajemen Agribisnis | I16: 3 | J16: Bodebekpunjur (Bogor, Depok, Bekasi, Puncak, Cianjur) | K16: Kota (Urban) | L16: Rumah Orang Tua/Wali | M16: Netral | N16: Tidak Menggambarkan diri saya | O16: Menggambarkan diri saya | P16: Cukup Menggambarkan diri saya | Q16: Sangat tidak menggambarkan diri saya | R16: Cukup Menggambarkan diri saya | S16: Menggambarkan diri saya | T16: Menggambarkan diri saya | U16: Tidak Menggambarkan diri saya | V16: Sangat menggambarkan diri saya | W16: Biru | X16: Menggambarkan diri saya | Y16: Netral | Z16: Cukup Menggambarkan diri saya | AA16: Netral | AB16: Menggambarkan diri saya | AC16: Sangat tidak menggambarkan diri saya | AD16: Tidak Menggambarkan diri saya | AE16: Tidak Menggambarkan diri saya | AF16: Netral | AG16: Cukup Setuju | AH16: Setuju | AI16: Netral | AJ16: Sangat Setuju | AK16: Cukup Setuju | AL16: Tidak Setuju | AM16: Cukup Setuju | AN16: Sangat Setuju | AO16: Cukup Setuju | AP16: Setuju | AQ16: Setuju | AR16: Sangat Setuju | AS16: Cukup Setuju | AT16: Setuju | AU16: Setuju | AV16: Hijau Tua | AW16: Sangat Setuju | AX16: Setuju | AY16: Sangat Setuju | AZ16: Cukup Setuju | BA16: Setuju | BB16: Sangat Setuju | BC16: Setuju | BD16: Cukup Setuju | BE16: Sangat Setuju | BF16: Kuning | BG16: Sangat Setuju | BH16: Setuju | BI16: Sangat Setuju | BJ16: Setuju | BK16: Sangat Setuju | BL16: Sangat Setuju | BM16: Cukup Setuju | BN16: Sangat Setuju | BO16: Cukup Setuju | BP16: Cukup Setuju | BQ16: Setuju | BR16: Sangat Tidak Setuju | BS16: Cukup Setuju | BT16: Sangat Setuju | BU16: Ungu | BV16: Cukup Setuju | BW16: Setuju | BX16: Sangat Setuju | BY16: Cukup Setuju | BZ16: Setuju | CA16: Sangat Setuju | CB16: Setuju | CC16: Sangat Setuju | CD16: Cukup Setuju | CE16: Sangat Setuju | CF16: Setuju | CG16: Sangat Setuju | CH16: Netral | CI16: Sangat Setuju | CJ16: Sangat Tidak Setuju | CK16: Tidak Setuju | CL16: Netral | CM16: Netral | CN16: Netral | CO16: Hijau | CP16: Sangat Tidak Setuju | CQ16: Tidak Setuju | CR16: Setuju | CS16: Sangat Setuju | CT16: Sering | CU16: Selalu | CV16: Selalu | CW16: Sering | CX16: Tidak Pernah | CY16: Kadang-Kadang | CZ16: Tidak Pernah | DA16: Jarang | DB16: Sering | DC16: Selalu | DD16: Selalu | DE16: Selalu | DF16: Jarang | DG16: Sering | DH16: Orange | DI16: Tidak Pernah | DJ16: Sering | DK16: Kadang-Kadang | DL16: Jarang | DM16: Selalu | DN16: melanihilda22@gmail.com
A17: 46249.491 | B17: Ya, saya bersedia berpartisipasi. | C17: Ya | D17: Putri | E17: Perempuan | F17: 19 | G17: IPB University | H17: Sekolah Vokasi/Manajemen Industri | I17: 3 | J17: Bodebekpunjur (Bogor, Depok, Bekasi, Puncak, Cianjur) | K17: Kota (Urban) | L17: Rumah Orang Tua/Wali | M17: Cukup Menggambarkan diri saya | N17: Cukup Menggambarkan diri saya | O17: Menggambarkan diri saya | P17: Netral | Q17: Cukup Tidak Menggambarkan diri saya | R17: Cukup Menggambarkan diri saya | S17: Cukup Menggambarkan diri saya | T17: Netral | U17: Cukup Menggambarkan diri saya | V17: Menggambarkan diri saya | W17: Biru | X17: Cukup Menggambarkan diri saya | Y17: Cukup Menggambarkan diri saya | Z17: Cukup Menggambarkan diri saya | AA17: Cukup Menggambarkan diri saya | AB17: Netral | AC17: Netral | AD17: Netral | AE17: Cukup Tidak Menggambarkan diri saya | AF17: Setuju | AG17: Setuju | AH17: Setuju | AI17: Setuju | AJ17: Cukup Setuju | AK17: Setuju | AL17: Setuju | AM17: Setuju | AN17: Cukup Setuju | AO17: Cukup Setuju | AP17: Setuju | AQ17: Cukup Setuju | AR17: Setuju | AS17: Setuju | AT17: Cukup Setuju | AU17: Tidak Setuju | AV17: Hijau Tua | AW17: Setuju | AX17: Tidak Setuju | AY17: Cukup Tidak Setuju | AZ17: Setuju | BA17: Tidak Setuju | BB17: Setuju | BC17: Tidak Setuju | BD17: Setuju | BE17: Tidak Setuju | BF17: Kuning | BG17: Setuju | BH17: Tidak Setuju | BI17: Setuju | BJ17: Tidak Setuju | BK17: Tidak Setuju | BL17: Setuju | BM17: Setuju | BN17: Tidak Setuju | BO17: Cukup Setuju | BP17: Cukup Tidak Setuju | BQ17: Setuju | BR17: Tidak Setuju | BS17: Tidak Setuju | BT17: Setuju | BU17: Ungu | BV17: Setuju | BW17: Tidak Setuju | BX17: Setuju | BY17: Setuju | BZ17: Cukup Tidak Setuju | CA17: Setuju | CB17: Tidak Setuju | CC17: Cukup Tidak Setuju | CD17: Setuju | CE17: Setuju | CF17: Setuju | CG17: Setuju | CH17: Setuju | CI17: Setuju | CJ17: Setuju | CK17: Setuju | CL17: Setuju | CM17: Setuju | CN17: Setuju | CO17: Hijau | CP17: Netral | CQ17: Netral | CR17: Netral | CS17: Setuju | CT17: Kadang-Kadang | CU17: Sering | CV17: Kadang-Kadang | CW17: Kadang-Kadang | CX17: Kadang-Kadang | CY17: Kadang-Kadang | CZ17: Kadang-Kadang | DA17: Jarang | DB17: Jarang | DC17: Tidak Pernah | DD17: Jarang | DE17: Tidak Pernah | DF17: Tidak Pernah | DG17: Tidak Pernah | DH17: Orange | DI17: Tidak Pernah | DJ17: Tidak Pernah | DK17: Tidak Pernah | DL17: Tidak Pernah | DM17: Jarang
A18: 46249.494 | B18: Ya, saya bersedia berpartisipasi. | C18: Ya | D18: Tla | E18: Perempuan | F18: 19 | G18: Institut Pertanian Bogor | H18: Sekolah Vokasi/Manajemen Agribisnis | I18: 3 | J18: Bodebekpunjur (Bogor, Depok, Bekasi, Puncak, Cianjur) | K18: Pinggiran Kota (Sub Urban) | L18: Rumah Orang Tua/Wali | M18: Cukup Menggambarkan diri saya | N18: Cukup Menggambarkan diri saya | O18: Sangat menggambarkan diri saya | P18: Cukup Menggambarkan diri saya | Q18: Sangat tidak menggambarkan diri saya | R18: Menggambarkan diri saya | S18: Sangat menggambarkan diri saya | T18: Cukup Menggambarkan diri saya | U18: Netral | V18: Netral | W18: Biru | X18: Cukup Menggambarkan diri saya | Y18: Sangat menggambarkan diri saya | Z18: Cukup Menggambarkan diri saya | AA18: Netral | AB18: Netral | AC18: Netral | AD18: Netral | AE18: Cukup Menggambarkan diri saya | AF18: Sangat Setuju | AG18: Cukup Setuju | AH18: Cukup Setuju | AI18: Cukup Setuju | AJ18: Netral | AK18: Netral | AL18: Cukup Setuju | AM18: Cukup Tidak Setuju | AN18: Cukup Setuju | AO18: Cukup Tidak Setuju | AP18: Cukup Setuju | AQ18: Cukup Tidak Setuju | AR18: Cukup Setuju | AS18: Cukup Setuju | AT18: Cukup Setuju | AU18: Tidak Setuju | AV18: Hijau Tua | AW18: Cukup Setuju | AX18: Cukup Tidak Setuju | AY18: Cukup Tidak Setuju | AZ18: Cukup Setuju | BA18: Sangat Tidak Setuju | BB18: Setuju | BC18: Cukup Tidak Setuju | BD18: Cukup Setuju | BE18: Cukup Setuju | BF18: Kuning | BG18: Sangat Setuju | BH18: Cukup Setuju | BI18: Cukup Setuju | BJ18: Sangat Tidak Setuju | BK18: Sangat Tidak Setuju | BL18: Sangat Setuju | BM18: Setuju | BN18: Sangat Tidak Setuju | BO18: Setuju | BP18: Tidak Setuju | BQ18: Cukup Setuju | BR18: Sangat Tidak Setuju | BS18: Tidak Setuju | BT18: Sangat Setuju | BU18: Ungu | BV18: Cukup Setuju | BW18: Cukup Tidak Setuju | BX18: Setuju | BY18: Setuju | BZ18: Cukup Setuju | CA18: Setuju | CB18: Cukup Tidak Setuju | CC18: Cukup Tidak Setuju | CD18: Sangat Setuju | CE18: Setuju | CF18: Setuju | CG18: Setuju | CH18: Setuju | CI18: Setuju | CJ18: Setuju | CK18: Netral | CL18: Sangat Setuju | CM18: Sangat Setuju | CN18: Setuju | CO18: Hijau | CP18: Setuju | CQ18: Netral | CR18: Setuju | CS18: Netral | CT18: Kadang-Kadang | CU18: Selalu | CV18: Kadang-Kadang | CW18: Kadang-Kadang | CX18: Jarang | CY18: Kadang-Kadang | CZ18: Jarang | DA18: Jarang | DB18: Jarang | DC18: Jarang | DD18: Kadang-Kadang | DE18: Tidak Pernah | DF18: Tidak Pernah | DG18: Jarang | DH18: Orange | DI18: Jarang | DJ18: Jarang | DK18: Tidak Pernah | DL18: Tidak Pernah | DM18: Jarang | DN18: 088289271441 (gopay)
A19: 46249.529 | B19: Ya, saya bersedia berpartisipasi. | C19: Ya | D19: J | E19: Perempuan | F19: 19 | G19: IPB University | H19: SV | I19: 3 | J19: Bodebekpunjur (Bogor, Depok, Bekasi, Puncak, Cianjur) | K19: Kota (Urban) | L19: Kos/Kontrakan | M19: Netral | N19: Cukup Tidak Menggambarkan diri saya | O19: Menggambarkan diri saya | P19: Netral | Q19: Sangat tidak menggambarkan diri saya | R19: Cukup Menggambarkan diri saya | S19: Menggambarkan diri saya | T19: Netral | U19: Cukup Tidak Menggambarkan diri saya | V19: Menggambarkan diri saya | W19: Biru | X19: Netral | Y19: Menggambarkan diri saya | Z19: Cukup Tidak Menggambarkan diri saya | AA19: Netral | AB19: Netral | AC19: Tidak Menggambarkan diri saya | AD19: Netral | AE19: Sangat tidak menggambarkan diri saya | AF19: Setuju | AG19: Cukup Setuju | AH19: Netral | AI19: Cukup Setuju | AJ19: Cukup Setuju | AK19: Cukup Setuju | AL19: Setuju | AM19: Setuju | AN19: Setuju | AO19: Tidak Setuju | AP19: Setuju | AQ19: Cukup Setuju | AR19: Setuju | AS19: Setuju | AT19: Setuju | AU19: Cukup Tidak Setuju | AV19: Hijau Tua | AW19: Cukup Setuju | AX19: Cukup Setuju | AY19: Cukup Tidak Setuju | AZ19: Cukup Setuju | BA19: Sangat Tidak Setuju | BB19: Setuju | BC19: Cukup Tidak Setuju | BD19: Cukup Setuju | BE19: Cukup Tidak Setuju | BF19: Kuning | BG19: Sangat Setuju | BH19: Sangat Tidak Setuju | BI19: Setuju | BJ19: Tidak Setuju | BK19: Cukup Setuju | BL19: Cukup Setuju | BM19: Setuju | BN19: Cukup Tidak Setuju | BO19: Cukup Setuju | BP19: Sangat Tidak Setuju | BQ19: Cukup Setuju | BR19: Cukup Setuju | BS19: Sangat Tidak Setuju | BT19: Cukup Setuju | BU19: Ungu | BV19: Cukup Setuju | BW19: Cukup Tidak Setuju | BX19: Cukup Tidak Setuju | BY19: Cukup Setuju | BZ19: Cukup Setuju | CA19: Cukup Setuju | CB19: Tidak Setuju | CC19: Cukup Setuju | CD19: Cukup Setuju | CE19: Setuju | CF19: Setuju | CG19: Setuju | CH19: Setuju | CI19: Setuju | CJ19: Setuju | CK19: Setuju | CL19: Setuju | CM19: Setuju | CN19: Setuju | CO19: Hijau | CP19: Setuju | CQ19: Setuju | CR19: Setuju | CS19: Setuju | CT19: Jarang | CU19: Sering | CV19: Kadang-Kadang | CW19: Sering | CX19: Jarang | CY19: Kadang-Kadang | CZ19: Tidak Pernah | DA19: Tidak Pernah | DB19: Tidak Pernah | DC19: Tidak Pernah | DD19: Tidak Pernah | DE19: Tidak Pernah | DF19: Tidak Pernah | DG19: Tidak Pernah | DH19: Orange | DI19: Tidak Pernah | DJ19: Tidak Pernah | DK19: Tidak Pernah | DL19: Tidak Pernah | DM19: Tidak Pernah | DN19: jeanraa.fh@gmail.com
A20: 46249.56 | B20: Ya, saya bersedia berpartisipasi. | C20: Ya | D20: H | E20: Perempuan | F20: 19 | G20: IPB | H20: MNI | I20: 5 | J20: Bodebekpunjur (Bogor, Depok, Bekasi, Puncak, Cianjur) | K20: Kota (Urban) | L20: Kos/Kontrakan | M20: Cukup Menggambarkan diri saya | N20: Menggambarkan diri saya | O20: Menggambarkan diri saya | P20: Sangat menggambarkan diri saya | Q20: Netral | R20: Cukup Menggambarkan diri saya | S20: Menggambarkan diri saya | T20: Menggambarkan diri saya | U20: Menggambarkan diri saya | V20: Menggambarkan diri saya | W20: Biru | X20: Menggambarkan diri saya | Y20: Menggambarkan diri saya | Z20: Menggambarkan diri saya | AA20: Cukup Menggambarkan diri saya | AB20: Netral | AC20: Cukup Menggambarkan diri saya | AD20: Cukup Menggambarkan diri saya | AE20: Menggambarkan diri saya | AF20: Setuju | AG20: Setuju | AH20: Cukup Setuju | AI20: Sangat Setuju | AJ20: Sangat Setuju | AK20: Setuju | AL20: Cukup Setuju | AM20: Cukup Setuju | AN20: Cukup Tidak Setuju | AO20: Cukup Setuju | AP20: Cukup Tidak Setuju | AQ20: Cukup Setuju | AR20: Cukup Setuju | AS20: Cukup Tidak Setuju | AT20: Cukup Setuju | AU20: Cukup Setuju | AV20: Hijau Tua | AW20: Setuju | AX20: Cukup Tidak Setuju | AY20: Cukup Setuju | AZ20: Cukup Tidak Setuju | BA20: Sangat Tidak Setuju | BB20: Sangat Setuju | BC20: Sangat Setuju | BD20: Tidak Setuju | BE20: Cukup Tidak Setuju | BF20: Kuning | BG20: Sangat Setuju | BH20: Sangat Tidak Setuju | BI20: Cukup Setuju | BJ20: Cukup Setuju | BK20: Cukup Tidak Setuju | BL20: Cukup Tidak Setuju | BM20: Setuju | BN20: Cukup Tidak Setuju | BO20: Cukup Tidak Setuju | BP20: Sangat Tidak Setuju | BQ20: Setuju | BR20: Cukup Setuju | BS20: Cukup Setuju | BT20: Sangat Setuju | BU20: Ungu | BV20: Cukup Setuju | BW20: Setuju | BX20: Setuju | BY20: Setuju | BZ20: Cukup Setuju | CA20: Setuju | CB20: Tidak Setuju | CC20: Cukup Tidak Setuju | CD20: Cukup Setuju | CE20: Sangat Setuju | CF20: Sangat Setuju | CG20: Sangat Setuju | CH20: Sangat Setuju | CI20: Sangat Setuju | CJ20: Sangat Setuju | CK20: Netral | CL20: Sangat Setuju | CM20: Sangat Setuju | CN20: Netral | CO20: Hijau | CP20: Netral | CQ20: Netral | CR20: Setuju | CS20: Setuju | CT20: Jarang | CU20: Kadang-Kadang | CV20: Kadang-Kadang | CW20: Jarang | CX20: Tidak Pernah | CY20: Jarang | CZ20: Jarang | DA20: Tidak Pernah | DB20: Sering | DC20: Sering | DD20: Sering | DE20: Tidak Pernah | DF20: Tidak Pernah | DG20: Tidak Pernah | DH20: Orange | DI20: Tidak Pernah | DJ20: Jarang | DK20: Tidak Pernah | DL20: Tidak Pernah | DM20: Kadang-Kadang | DN20: cahayahana7@gmail.com
A21: 46249.732 | B21: Ya, saya bersedia berpartisipasi. | C21: Ya | D21: Danish | E21: Perempuan | F21: 20 | G21: Institut Pertanian Bogor | H21: Manajemen Agribisnis | I21: 5 | J21: Bodebekpunjur (Bogor, Depok, Bekasi, Puncak, Cianjur) | K21: Kota (Urban) | L21: Kos/Kontrakan | M21: Sangat menggambarkan diri saya | N21: Cukup Menggambarkan diri saya | O21: Sangat menggambarkan diri saya | P21: Sangat menggambarkan diri saya | Q21: Menggambarkan diri saya | R21: Menggambarkan diri saya | S21: Sangat menggambarkan diri saya | T21: Sangat menggambarkan diri saya | U21: Sangat menggambarkan diri saya | V21: Sangat menggambarkan diri saya | W21: Biru | X21: Menggambarkan diri saya | Y21: Sangat menggambarkan diri saya | Z21: Sangat menggambarkan diri saya | AA21: Sangat menggambarkan diri saya | AB21: Sangat menggambarkan diri saya | AC21: Sangat menggambarkan diri saya | AD21: Sangat menggambarkan diri saya | AE21: Sangat menggambarkan diri saya | AF21: Sangat Setuju | AG21: Sangat Setuju | AH21: Sangat Setuju | AI21: Sangat Setuju | AJ21: Sangat Setuju | AK21: Sangat Setuju | AL21: Cukup Setuju | AM21: Cukup Setuju | AN21: Cukup Tidak Setuju | AO21: Cukup Tidak Setuju | AP21: Cukup Setuju | AQ21: Cukup Tidak Setuju | AR21: Setuju | AS21: Setuju | AT21: Setuju | AU21: Cukup Setuju | AV21: Hijau Tua | AW21: Cukup Setuju | AX21: Cukup Setuju | AY21: Cukup Setuju | AZ21: Cukup Setuju | BA21: Sangat Tidak Setuju | BB21: Setuju | BC21: Cukup Tidak Setuju | BD21: Cukup Setuju | BE21: Cukup Tidak Setuju | BF21: Kuning | BG21: Setuju | BH21: Cukup Tidak Setuju | BI21: Cukup Setuju | BJ21: Cukup Setuju | BK21: Cukup Setuju | BL21: Tidak Setuju | BM21: Cukup Setuju | BN21: Cukup Setuju | BO21: Setuju | BP21: Tidak Setuju | BQ21: Cukup Setuju | BR21: Cukup Tidak Setuju | BS21: Cukup Tidak Setuju | BT21: Cukup Setuju | BU21: Ungu | BV21: Cukup Setuju | BW21: Cukup Tidak Setuju | BX21: Cukup Setuju | BY21: Setuju | BZ21: Cukup Setuju | CA21: Setuju | CB21: Cukup Tidak Setuju | CC21: Cukup Setuju | CD21: Setuju | CE21: Setuju | CF21: Setuju | CG21: Setuju | CH21: Setuju | CI21: Setuju | CJ21: Setuju | CK21: Setuju | CL21: Setuju | CM21: Setuju | CN21: Setuju | CO21: Hijau | CP21: Setuju | CQ21: Setuju | CR21: Setuju | CS21: Setuju | CT21: Kadang-Kadang | CU21: Kadang-Kadang | CV21: Kadang-Kadang | CW21: Kadang-Kadang | CX21: Kadang-Kadang | CY21: Sering | CZ21: Sering | DA21: Sering | DB21: Sering | DC21: Sering | DD21: Kadang-Kadang | DE21: Kadang-Kadang | DF21: Sering | DG21: Sering | DH21: Orange | DI21: Sering | DJ21: Sering | DK21: Sering | DL21: Sering | DM21: Kadang-Kadang | DN21: danisharamumtaz02@gmail.com
A22: 46249.764 | B22: Ya, saya bersedia berpartisipasi. | C22: Ya | D22: Syifa | E22: Perempuan | F22: 19 | G22: IPB University | H22: Manajemen Industri | I22: 5 | J22: Bodebekpunjur (Bogor, Depok, Bekasi, Puncak, Cianjur) | K22: Kota (Urban) | L22: Kos/Kontrakan | M22: Menggambarkan diri saya | N22: Netral | O22: Menggambarkan diri saya | P22: Menggambarkan diri saya | Q22: Menggambarkan diri saya | R22: Menggambarkan diri saya | S22: Menggambarkan diri saya | T22: Menggambarkan diri saya | U22: Menggambarkan diri saya | V22: Menggambarkan diri saya | W22: Biru | X22: Menggambarkan diri saya | Y22: Menggambarkan diri saya | Z22: Menggambarkan diri saya | AA22: Menggambarkan diri saya | AB22: Menggambarkan diri saya | AC22: Menggambarkan diri saya | AD22: Menggambarkan diri saya | AE22: Menggambarkan diri saya | AF22: Setuju | AG22: Setuju | AH22: Setuju | AI22: Setuju | AJ22: Setuju | AK22: Setuju | AL22: Setuju | AM22: Setuju | AN22: Setuju | AO22: Setuju | AP22: Setuju | AQ22: Setuju | AR22: Setuju | AS22: Setuju | AT22: Setuju | AU22: Setuju | AV22: Hijau Tua | AW22: Setuju | AX22: Setuju | AY22: Setuju | AZ22: Setuju | BA22: Sangat Tidak Setuju | BB22: Setuju | BC22: Setuju | BD22: Setuju | BE22: Sangat Tidak Setuju | BF22: Kuning | BG22: Setuju | BH22: Sangat Tidak Setuju | BI22: Setuju | BJ22: Tidak Setuju | BK22: Sangat Tidak Setuju | BL22: Setuju | BM22: Setuju | BN22: Sangat Tidak Setuju | BO22: Setuju | BP22: Sangat Tidak Setuju | BQ22: Setuju | BR22: Setuju | BS22: Cukup Setuju | BT22: Cukup Setuju | BU22: Ungu | BV22: Setuju | BW22: Cukup Setuju | BX22: Cukup Setuju | BY22: Setuju | BZ22: Setuju | CA22: Setuju | CB22: Sangat Tidak Setuju | CC22: Setuju | CD22: Cukup Setuju | CE22: Setuju | CF22: Setuju | CG22: Setuju | CH22: Setuju | CI22: Setuju | CJ22: Setuju | CK22: Setuju | CL22: Setuju | CM22: Setuju | CN22: Setuju | CO22: Hijau | CP22: Setuju | CQ22: Setuju | CR22: Setuju | CS22: Setuju | CT22: Kadang-Kadang | CU22: Sering | CV22: Sering | CW22: Sering | CX22: Sering | CY22: Kadang-Kadang | CZ22: Kadang-Kadang | DA22: Kadang-Kadang | DB22: Jarang | DC22: Jarang | DD22: Jarang | DE22: Jarang | DF22: Tidak Pernah | DG22: Sering | DH22: Orange | DI22: Jarang | DJ22: Jarang | DK22: Sering | DL22: Kadang-Kadang | DM22: Kadang-Kadang | DN22: Dana / 085700912878
